Workbook

Sheet Assumptions
A1: PE / PRIVATE CREDIT FUND — MODEL ASSUMPTIONS
A3: FUND PARAMETERS
A4: Fund Name | B4: Alter Domus Private Credit Fund I [Illustrative] | C4: Example only — for interview use
A5: Fund Currency | B5: £ (British Pounds Sterling) | C5: All figures in £
A6: Fund Size — Total Committed Capital | B6: 100000000 | C6: Sum of all LP + GP commitments
A7: GP Commitment % | B7: 0.02 | C7: GP commits 2% alongside LPs
A8: GP Commitment £ | B8: =B6*B7 -> 2000000
A9: Total LP Commitment £ | B9: =B6-B8 -> 98000000
A10: Fund Life (Years) | B10: 10 | C10: Year 1 to Year 10
A11: Investment Period (Years) | B11: 5 | C11: New investments made only in Years 1–5
A12: Fund Start Year | B12: 2015
A14: FEE STRUCTURE
A15: Management Fee — Investment Period (Yrs 1–5) | B15: 0.02 | C15: % of committed capital p.a.
A16: Management Fee — Harvest Period (Yrs 6–10) | B16: 0.015 | C16: % of invested cost basis p.a.
A17: Other Fund Expenses (admin, legal, audit) | B17: 0.001 | C17: % of committed capital p.a.
A19: WATERFALL PARAMETERS
A20: Preferred Return / Hurdle Rate | B20: 0.08 | C20: Annual compounded return to LPs before GP earns carry
A21: Carried Interest — GP Share | B21: 0.2 | C21: GP earns 20% of profits above the hurdle
A22: Carried Interest — LP Share | B22: =1-B21 -> 0.8
A23: GP Catch-up Rate | B23: 1 | C23: 100% = GP gets 100% of distrib. until it catches up to its full carry entitlement
A24: GP Catch-up Fraction (= Carry% ÷ LP Carry%) | B24: =B21/(1-B21) -> 0.25 | C24: GP catch-up = this % × preferred return (ensures GP gets exactly 20% of total profits)
A25: Waterfall Type | B25: European (Whole-Fund) | C25: European: ALL LP capital + ALL preferred return returned before GP sees any carry
A26: American Waterfall also shown? | B26: Yes — see American Waterfall sheet | C26: Deal-by-deal carry; clawback reconciliation at fund end
A27: Clawback Provision | B27: Yes | C27: GP must return excess carry received under American vs European waterfall
A29: LP COMMITMENT TABLE
A30: Investor | B30: Commitment (£) | C30: % of Fund
A31: LP A | B31: 35000000 | C31: =B31/B6 -> 0.35
A32: LP B | B32: 28000000 | C32: =B32/B6 -> 0.28
A33: LP C | B33: 20000000 | C33: =B33/B6 -> 0.2
A34: LP D | B34: 15000000 | C34: =B34/B6 -> 0.15
A35: GP (General Partner) | B35: =B8 -> 2000000 | C35: =B35/B6 -> 0.02
A36: TOTAL COMMITTED | B36: =SUM(B31:B35) -> 100000000 | C36: =B36/B6 -> 1
A38: CAPITAL CALL SCHEDULE
A39: Capital Call | B39: % of Commitment Called | C39: Notes
A40: Call 1 — Year 1 (Fund Inception) | B40: 0.25 | C40: First deployment tranche; management fees begin accruing
A41: Call 2 — Year 2 | B41: 0.25 | C41: Second tranche; deals being sourced and signed
A42: Call 3 — Year 3 | B42: 0.2 | C42: Mid-investment-period tranche
A43: Call 4 — Year 4 | B43: 0.2 | C43: Late investment-period capital draw
A44: Call 5 — Year 5 (Final Draw) | B44: 0.05 | C44: Final close; investment period ends; harvest period begins
A45: Total Capital Called | B45: =SUM(B40:B44) -> 0.95 | C45: Unfunded commitment = 5% (not called)

Sheet Capital_Calls
A1: CAPITAL CALL SCHEDULE — LP ACCOUNT TRACKING
A2: All amounts in £. Blue = inputs. Black = formulas. Commitment % drawn per call sourced from Assumptions sheet.
A4: Investor | B4: Commitment (£) | C4: Call 1 Yr 1 25% | D4: Call 2 Yr 2 25% | E4: Call 3 Yr 3 20% | F4: Call 4 Yr 4 20% | G4: Call 5 Yr 5 5% | H4: Total Called (£) | I4: Unfunded Commitment (£)
A5: LP A | B5: =Assumptions!B31 -> 35000000 | C5: =B5*Assumptions!B40 -> 8750000 | D5: =B5*Assumptions!B41 -> 8750000 | E5: =B5*Assumptions!B42 -> 7000000 | F5: =B5*Assumptions!B43 -> 7000000 | G5: =B5*Assumptions!B44 -> 1750000 | H5: =SUM(C5:G5) -> 33250000 | I5: =B5-H5 -> 1750000
A6: LP B | B6: =Assumptions!B32 -> 28000000 | C6: =B6*Assumptions!B40 -> 7000000 | D6: =B6*Assumptions!B41 -> 7000000 | E6: =B6*Assumptions!B42 -> 5600000 | F6: =B6*Assumptions!B43 -> 5600000 | G6: =B6*Assumptions!B44 -> 1400000 | H6: =SUM(C6:G6) -> 26600000 | I6: =B6-H6 -> 1400000
A7: LP C | B7: =Assumptions!B33 -> 20000000 | C7: =B7*Assumptions!B40 -> 5000000 | D7: =B7*Assumptions!B41 -> 5000000 | E7: =B7*Assumptions!B42 -> 4000000 | F7: =B7*Assumptions!B43 -> 4000000 | G7: =B7*Assumptions!B44 -> 1000000 | H7: =SUM(C7:G7) -> 19000000 | I7: =B7-H7 -> 1000000
A8: LP D | B8: =Assumptions!B34 -> 15000000 | C8: =B8*Assumptions!B40 -> 3750000 | D8: =B8*Assumptions!B41 -> 3750000 | E8: =B8*Assumptions!B42 -> 3000000 | F8: =B8*Assumptions!B43 -> 3000000 | G8: =B8*Assumptions!B44 -> 750000 | H8: =SUM(C8:G8) -> 14250000 | I8: =B8-H8 -> 750000
A9: GP | B9: =Assumptions!B35 -> 2000000 | C9: =B9*Assumptions!B40 -> 500000 | D9: =B9*Assumptions!B41 -> 500000 | E9: =B9*Assumptions!B42 -> 400000 | F9: =B9*Assumptions!B43 -> 400000 | G9: =B9*Assumptions!B44 -> 100000 | H9: =SUM(C9:G9) -> 1900000 | I9: =B9-H9 -> 100000
A10: TOTAL | B10: =SUM(B5:B9) -> 100000000 | C10: =SUM(C5:C9) -> 25000000 | D10: =SUM(D5:D9) -> 25000000 | E10: =SUM(E5:E9) -> 20000000 | F10: =SUM(F5:F9) -> 20000000 | G10: =SUM(G5:G9) -> 5000000 | H10: =SUM(H5:H9) -> 95000000 | I10: =SUM(I5:I9) -> 5000000
A12: KEY CONCEPTS | Capital Call: A formal notice from the GP requiring LPs to transfer their committed capital on a specified date. | Unfunded Commitment: The portion of an LP's commitment not yet called. | LP account tracks: Contributed Capital, Unfunded Commitment, and (later) Distributions Received.

Sheet Deal_Tracker
A1: DEAL TRACKER — PORTFOLIO INVESTMENTS
A2: Gross returns (before management fees and waterfall allocations). Preferred return per deal used as input in American Waterfall sheet.
A4: Deal / Company | B4: Sector | C4: Investment Year | D4: £ Invested | E4: Exit Year | F4: Holding Period (Yrs) | G4: Exit Proceeds / NAV (£) | H4: Gross MoIC | I4: Gross IRR | J4: Status
A5: Deal 1 — Epsilon Holdings | B5: Healthcare | C5: 2015 | D5: 15000000 | E5: 2018 | F5: =E5-C5 -> 3 | G5: 42000000 | H5: =G5/D5 -> 2.8 | I5: =IF(F5>0,POWER(G5/D5,1/F5)-1,"N/A") -> 0.40945975 | J5: Realised
A6: Deal 2 — Talon Credit | B6: Retail | C6: 2015 | D6: 12000000 | E6: 2019 | F6: =E6-C6 -> 4 | G6: 7000000 | H6: =G6/D6 -> 0.58333333 | I6: =IF(F6>0,POWER(G6/D6,1/F6)-1,"N/A") -> -0.12606487 | J6: Realised ⚠ Loss
A7: Deal 3 — Meridian Infra | B7: Infrastructure | C7: 2016 | D7: 22000000 | E7: 2021 | F7: =E7-C7 -> 5 | G7: 70000000 | H7: =G7/D7 -> 3.1818182 | I7: =IF(F7>0,POWER(G7/D7,1/F7)-1,"N/A") -> 0.26047742 | J7: Realised
A8: Deal 4 — Apex Logistics | B8: Industrials | C8: 2017 | D8: 18000000 | E8: 2022 | F8: =E8-C8 -> 5 | G8: 55000000 | H8: =G8/D8 -> 3.0555556 | I8: =IF(F8>0,POWER(G8/D8,1/F8)-1,"N/A") -> 0.25031096 | J8: Realised
A9: Deal 5 — Solaris Energy | B9: Energy | C9: 2018 | D9: 15000000 | E9: Held | F9: =2021-C9 -> 3 | G9: 28000000 | H9: =G9/D9 -> 1.8666667 | I9: =IF(F9>0,POWER(G9/D9,1/F9)-1,"N/A") -> 0.2312765 | J9: Unrealised (NAV)
A10: TOTAL / FUND AGGREGATE | D10: =SUM(D5:D9) -> 82000000 | G10: =SUM(G5:G9) -> 202000000 | H10: =G10/D10 -> 2.4634146 | J10: All 5 deals combined
A12: PREFERRED RETURN REFERENCE — Per Deal (used in American Waterfall) | Formula: Invested × (POWER(1 + Hurdle, Holding Years) − 1)
A13: Deal | B13: £ Invested | C13: Holding Yrs | D13: Hurdle Rate | E13: Preferred Return (£) | J13: Notes
A14: Deal 1 — Epsilon Holdings | B14: =D5 -> 15000000 | C14: =F5 -> 3 | D14: =Assumptions!B20 -> 0.08 | E14: =B14*(POWER(1+D14,C14)-1) -> 3895680 | J14: Compounded preferred return accrued on invested capital over holding period
A15: Deal 2 — Talon Credit | B15: =D6 -> 12000000 | C15: =F6 -> 4 | D15: =Assumptions!B20 -> 0.08 | E15: =B15*(POWER(1+D15,C15)-1) -> 4325867.5 | J15: Compounded preferred return accrued on invested capital over holding period
A16: Deal 3 — Meridian Infra | B16: =D7 -> 22000000 | C16: =F7 -> 5 | D16: =Assumptions!B20 -> 0.08 | E16: =B16*(POWER(1+D16,C16)-1) -> 10325218 | J16: Compounded preferred return accrued on invested capital over holding period
A17: Deal 4 — Apex Logistics | B17: =D8 -> 18000000 | C17: =F8 -> 5 | D17: =Assumptions!B20 -> 0.08 | E17: =B17*(POWER(1+D17,C17)-1) -> 8447905.4 | J17: Compounded preferred return accrued on invested capital over holding period
A18: Deal 5 — Solaris Energy | B18: =D9 -> 15000000 | C18: =F9 -> 3 | D18: =Assumptions!B20 -> 0.08 | E18: =B18*(POWER(1+D18,C18)-1) -> 3895680 | J18: Compounded preferred return accrued on invested capital over holding period

Sheet European_Waterfall
A1: EUROPEAN WATERFALL — WHOLE-FUND BASIS
A2: European Waterfall: GP earns NO carried interest until ALL LP capital across the ENTIRE fund has been returned PLUS full preferred return earned. This is the LP-friendly structure — it protects investors from early exits subsidising GP carry while later deals underperform.
A4: SECTION A — FUND-LEVEL CASH FLOWS
A5: Line Item | B5: £ Amount | C5: % of Capital Called | D5: Notes / Formula
A6: Total LP Committed Capital | B6: =Assumptions!B9 -> 98000000 | C6: =Assumptions!B9/Assumptions!B6 -> 0.98 | D6: LP only (excl. GP)
A7: GP Committed Capital | B7: =Assumptions!B8 -> 2000000 | C7: =Assumptions!B8/Assumptions!B6 -> 0.02 | D7: 2% GP commitment
A8: TOTAL Fund Committed Capital | B8: =Assumptions!B6 -> 100000000 | C8: =1 -> 1 | D8: =Assumptions!B6 -> 100000000
A10: % of Commitment Actually Called | B10: =Assumptions!B45 -> 0.95 | D10: 95% (5% uncalled)
A11: LP Capital Contributed (Called — Tier 1 Basis) | B11: =Assumptions!B9*Assumptions!B45 -> 93100000 | D11: =Assumptions!B9*Assumptions!B45 -> 93100000
A12: Capital Deployed into Deals | B12: =Deal_Tracker!D10 -> 82000000 | D12: =Deal_Tracker!D10 -> 82000000
A13: Management Fees Paid (est.) | B13: =-((Assumptions!B15*Assumptions!B6*5)+(Assumptions!B16*Deal_Tracker!D10*5)) -> -16150000 | D13: Inv period: 2%×£100m×5yrs + Harvest: 1.5%×£82m×5yrs
A15: SECTION B — FUND PROCEEDS
A16: Item | B16: £ Amount | C16: Source | D16: Notes
A17: Total Exit Proceeds (Realised — Deals 1–4) | B17: =SUM(Deal_Tracker!G5:G8) -> 174000000 | C17: Deal Tracker | D17: Sum of realised exit proceeds
A18: Unrealised NAV — Deal 5 (Held at Current Value) | B18: =Deal_Tracker!G9 -> 28000000 | C18: Deal Tracker | D18: Marked to current fair value; treated as distributable for waterfall calc
A19: GROSS TOTAL PROCEEDS (Realised + NAV) | B19: =B17+B18 -> 202000000 | D19: =B17+B18 -> 202000000
A21: SECTION C — PREFERRED RETURN CALCULATION
A22: Preferred Return = LP Capital Called per tranche × (POWER(1 + Hurdle, Years Outstanding) − 1) | Each tranche runs from its call year until fund end (Year 10).
A23: Capital Call Tranche | B23: LP Capital Called (£) | C23: Years Outstanding | D23: Preferred Return Earned (£)
A24: Call 1 — Year 1 | B24: =Assumptions!B9*Assumptions!B40 -> 24500000 | C24: =Assumptions!B10-(1-1) -> 10 | D24: =B24*(POWER(1+Assumptions!B20,C24)-1) -> 28393662
A25: Call 2 — Year 2 | B25: =Assumptions!B9*Assumptions!B41 -> 24500000 | C25: =Assumptions!B10-(2-1) -> 9 | D25: =B25*(POWER(1+Assumptions!B20,C25)-1) -> 24475613
A26: Call 3 — Year 3 | B26: =Assumptions!B9*Assumptions!B42 -> 19600000 | C26: =Assumptions!B10-(3-1) -> 8 | D26: =B26*(POWER(1+Assumptions!B20,C26)-1) -> 16678232
A27: Call 4 — Year 4 | B27: =Assumptions!B9*Assumptions!B43 -> 19600000 | C27: =Assumptions!B10-(4-1) -> 7 | D27: =B27*(POWER(1+Assumptions!B20,C27)-1) -> 13990956
A28: Call 5 — Year 5 | B28: =Assumptions!B9*Assumptions!B44 -> 4900000 | C28: =Assumptions!B10-(5-1) -> 6 | D28: =B28*(POWER(1+Assumptions!B20,C28)-1) -> 2875684.2
A29: TOTAL PREFERRED RETURN OWED TO LPs | B29: =SUM(B24:B28) -> 93100000 | D29: =SUM(D24:D28) -> 86414148
A31: SECTION D — WATERFALL DISTRIBUTION (European / Whole-Fund)
A32: Waterfall Tier | B32: Total Amount (£) | C32: To LP (£) | D32: To GP (£)
A33: Available for Distribution = Total Gross Proceeds
A34: TIER 1 — Return of LP Contributed Capital | B34: =MIN(B19,B11) -> 93100000 | C34: =B34 -> 93100000 | D34: =0 -> 0
A35: ↳ LPs receive back 100% of contributed capital before GP gets anything. Tier 1 amount = MIN(Total Proceeds, LP Capital Contributed).
A36: Remaining After Tier 1 | B36: =B19-B34 -> 108900000
A38: TIER 2 — Preferred Return (8% p.a. Compounded) | B38: =MIN(B36,D29) -> 86414148 | C38: =B38 -> 86414148 | D38: =0 -> 0
A39: ↳ LPs earn 8% p.a. compounded on all capital called, per tranche, from call date to fund end. Tier 2 = MIN(Remaining, Total Preferred Return Owed).
A40: Remaining After Tier 2 | B40: =B36-B38 -> 22485852
A42: TIER 3 — GP Catch-Up (100%) | B42: =MIN(B40,Assumptions!B24*D29) -> 21603537 | C42: =0 -> 0 | D42: =B42 -> 21603537
A43: ↳ GP Catch-up = MIN(Remaining, 25% × Preferred Return) | The 25% = Carry% ÷ LP_Share (20%÷80%) | This gives GP exactly 20% of total profits (Preferred Return + Super-Profit) before the Tier 4 split.
A44: Remaining After Tier 3 | B44: =B40-B42 -> 882315.29
A46: TIER 4 — Carried Interest Split (80% LP / 20% GP) | B46: =B44 -> 882315.29 | C46: =B44*Assumptions!B22 -> 705852.23 | D46: =B44*Assumptions!B21 -> 176463.06
A47: ↳ Remaining super-profit (above capital + hurdle) split 80% to LPs and 20% to GP as carried interest. LP% = 1 − Carry%.
A49: SECTION E — WATERFALL SUMMARY & RECONCILIATION
...

Sheet American_Waterfall
A1: AMERICAN WATERFALL — DEAL-BY-DEAL BASIS
A2: American Waterfall: carried interest is calculated and distributed after EACH individual deal exits — GP earns carry deal-by-deal regardless of whether the overall fund has returned LP capital. GP-friendly; requires a clawback provision to correct overpayment at fund end.
A4: Waterfall Tier | B4: Deal 1 Epsilon (£) | C4: Deal 2 Talon (£) | D4: Deal 3 Meridian (£) | E4: Deal 4 Apex (£) | F4: Deal 5 Solaris (£) | G4: TOTAL All Deals (£) | H4: Notes
A5: INPUTS (from Deal Tracker)
A6: Exit Proceeds / NAV (£) | B6: =Deal_Tracker!G5 -> 42000000 | C6: =Deal_Tracker!G6 -> 7000000 | D6: =Deal_Tracker!G7 -> 70000000 | E6: =Deal_Tracker!G8 -> 55000000 | F6: =Deal_Tracker!G9 -> 28000000 | G6: =SUM(B6:F6) -> 202000000 | H6: Total gross proceeds per deal
A7: £ Invested | B7: =Deal_Tracker!D5 -> 15000000 | C7: =Deal_Tracker!D6 -> 12000000 | D7: =Deal_Tracker!D7 -> 22000000 | E7: =Deal_Tracker!D8 -> 18000000 | F7: =Deal_Tracker!D9 -> 15000000 | G7: =SUM(B7:F7) -> 82000000 | H7: Capital deployed
A8: Holding Period (Years) | B8: =Deal_Tracker!F5 -> 3 | C8: =Deal_Tracker!F6 -> 4 | D8: =Deal_Tracker!F7 -> 5 | E8: =Deal_Tracker!F8 -> 5 | F8: =Deal_Tracker!F9 -> 3 | G8: —
A9: Preferred Return per Deal (£) | B9: =Deal_Tracker!E14 -> 3895680 | C9: =Deal_Tracker!E15 -> 4325867.5 | D9: =Deal_Tracker!E16 -> 10325218 | E9: =Deal_Tracker!E17 -> 8447905.4 | F9: =Deal_Tracker!E18 -> 3895680 | G9: =SUM(B9:F9) -> 30890351 | H9: From Deal Tracker preferred return table
A11: WATERFALL CALCULATION (each deal independently)
A12: TIER 1 — Return of LP Capital | B12: =MIN(B6,B7) -> 15000000 | C12: =MIN(C6,C7) -> 7000000 | D12: =MIN(D6,D7) -> 22000000 | E12: =MIN(E6,E7) -> 18000000 | F12: =MIN(F6,F7) -> 15000000 | G12: =SUM(B12:F12) -> 77000000 | H12: MIN(Proceeds, Capital Invested) — LP gets back invested capital first
A13: Remaining After Tier 1 | B13: =B6-B12 -> 27000000 | C13: =C6-C12 -> 0 | D13: =D6-D12 -> 48000000 | E13: =E6-E12 -> 37000000 | F13: =F6-F12 -> 13000000 | G13: =SUM(B13:F13) -> 125000000 | H13: Available for preferred return
A14: TIER 2 — Preferred Return (8% Compounded) | B14: =MIN(B13,B9) -> 3895680 | C14: =MIN(C13,C9) -> 0 | D14: =MIN(D13,D9) -> 10325218 | E14: =MIN(E13,E9) -> 8447905.4 | F14: =MIN(F13,F9) -> 3895680 | G14: =SUM(B14:F14) -> 26564483 | H14: MIN(Remaining, PR Earned) — 0 if deal returned less than capital
A15: Remaining After Tier 2 | B15: =B13-B14 -> 23104320 | C15: =C13-C14 -> 0 | D15: =D13-D14 -> 37674782 | E15: =E13-E14 -> 28552095 | F15: =F13-F14 -> 9104320 | G15: =SUM(B15:F15) -> 98435517 | H15: Super-profit available for GP catch-up
A16: TIER 3 — GP Catch-up (100% to GP) | B16: =MIN(B15,Assumptions!B24*B9) -> 973920 | C16: =MIN(C15,Assumptions!B24*C9) -> 0 | D16: =MIN(D15,Assumptions!B24*D9) -> 2581304.4 | E16: =MIN(E15,Assumptions!B24*E9) -> 2111976.3 | F16: =MIN(F15,Assumptions!B24*F9) -> 973920 | G16: =SUM(B16:F16) -> 6641120.8 | H16: MIN(Remaining, 25% × PR) — GP earns 25% of PR to reach 20% of total profit
A17: Remaining After Tier 3 | B17: =B15-B16 -> 22130400 | C17: =C15-C16 -> 0 | D17: =D15-D16 -> 35093478 | E17: =E15-E16 -> 26440118 | F17: =F15-F16 -> 8130400 | G17: =SUM(B17:F17) -> 91794396 | H17: Final super-profit for 80/20 split
A18: TIER 4 — Carried Interest Split (80% LP / 20% GP)
A19: LP Share (80%) | B19: =B17*Assumptions!B22 -> 17704320 | C19: =C17*Assumptions!B22 -> 0 | D19: =D17*Assumptions!B22 -> 28074782 | E19: =E17*Assumptions!B22 -> 21152095 | F19: =F17*Assumptions!B22 -> 6504320 | G19: =SUM(B19:F19) -> 73435517
A20: GP Share (20% Carry) | B20: =B17*Assumptions!B21 -> 4426080 | C20: =C17*Assumptions!B21 -> 0 | D20: =D17*Assumptions!B21 -> 7018695.6 | E20: =E17*Assumptions!B21 -> 5288023.7 | F20: =F17*Assumptions!B21 -> 1626080 | G20: =SUM(B20:F20) -> 18358879
A22: DISTRIBUTION SUMMARY PER DEAL
A23: Total to LP (T1+T2+T4_LP) | B23: =B12+B14+B19 -> 36600000 | C23: =C12+C14+C19 -> 7000000 | D23: =D12+D14+D19 -> 60400000 | E23: =E12+E14+E19 -> 47600000 | F23: =F12+F14+F19 -> 25400000 | G23: =SUM(B23:F23) -> 177000000
A24: Total to GP (T3+T4_GP) | B24: =B16+B20 -> 5400000 | C24: =C16+C20 -> 0 | D24: =D16+D20 -> 9600000 | E24: =E16+E20 -> 7400000 | F24: =F16+F20 -> 2600000 | G24: =SUM(B24:F24) -> 25000000 | H24: GP's carry per deal
A25: CHECK (should = Proceeds) | B25: =B23+B24-B6 -> 0 | C25: =C23+C24-C6 -> 0 | D25: =D23+D24-D6 -> 0 | E25: =E23+E24-E6 -> 0 | F25: =F23+F24-F6 -> 0 | G25: =SUM(B25:F25) -> 0 | H25: Must be zero for every deal
A27: AMERICAN vs EUROPEAN COMPARISON — CLAWBACK ANALYSIS
A28: At fund end, if GP received MORE carry under American waterfall (deal-by-deal) than it was entitled to under European (whole-fund), it must return the excess to LPs — this is the CLAWBACK. Deal 2 (Talon — loss deal) earns no carry; but the GP already banked carry from Deals 1 & 3 under American rules. European waterfall forces netting across the whole portfolio.
A29: Metric | B29: £ Amount | C29: Notes
A30: GP Total Carry — American Waterfall (Deal-by-Deal) | B30: =G24 -> 25000000 | C30: Sum of GP carry across all 5 deals above
A31: GP Total Carry — European Waterfall (Whole-Fund) | B31: =European_Waterfall!D42+European_Waterfall!D46 -> 21780000 | C31: From European Waterfall sheet
A32: CLAWBACK AMOUNT (GP must return to LPs) | B32: =MAX(0,B30-B31) -> 3220000 | C32: Only triggered if American > European; never negative
A33: Net GP Carry After Clawback | B33: =B30-B32 -> 21780000 | C33: Should equal European waterfall GP carry
A34: CHECK: Net GP = European GP Carry | B34: =B33-B31 -> 0 | C34: Must equal zero

Sheet Performance_Summary
A1: FUND PERFORMANCE METRICS — DASHBOARD
A2: Performance metrics measure the total return of the fund from LP perspective. TVPI = how much money LPs get back per £1 invested. DPI = realised multiple. RVPI = unrealised. IRR = compound annual return. These are the standard metrics Alter Domus and all PE administrators report.
A4: SECTION A — FUND-LEVEL MULTIPLES (TVPI / DPI / RVPI)
A5: Metric | B5: Value | C5: Formula / Explanation
A6: Total LP Capital Contributed (Called-In Capital) | B6: =European_Waterfall!B11 -> 93100000 | C6: LP commitments × 95% called. This is the denominator for all per-£ metrics.
A7: Realised Proceeds (Deals 1–4) | B7: =SUM(Deal_Tracker!G5:G8) -> 174000000 | C7: Exit proceeds actually received; cash in LP bank accounts
A8: Unrealised NAV (Deal 5 — Solaris) | B8: =Deal_Tracker!G9 -> 28000000 | C8: Marked at current fair value (Level 3 in IFRS 13 hierarchy for private assets)
A9: Total Value (Realised + Unrealised) | B9: =B7+B8 -> 202000000 | C9: Total distributions + remaining NAV
A11: TVPI (Total Value to Paid-In) | B11: =B9/B6 -> 2.16971 | C11: Formula: Total Value / LP Capital Called. Best overall return summary.
A12: DPI (Distributions to Paid-In) | B12: =B7/B6 -> 1.8689581 | C12: Formula: Realised Proceeds / LP Capital. Cash-on-cash; money actually received by LPs.
A13: RVPI (Residual Value to Paid-In) | B13: =B8/B6 -> 0.30075188 | C13: Formula: Unrealised NAV / LP Capital. Paper value still in fund; subject to Level 3 valuation.
A14: CHECK: TVPI = DPI + RVPI | B14: =B11-B12-B13 -> 0 | C14: Must be zero — confirms TVPI = DPI + RVPI identity holds.
A16: SECTION B — FUND IRR (Approximation Using Annual Cash Flows)
A17: Description | B17: Value | C17: Explanation
A18: IRR = the discount rate at which the NPV of all LP cash flows (calls out, distributions in) equals zero. Below, LP cash flows are set up year by year. The IRR() function in Excel solves for this rate. For precise results, use XIRR() with actual dates.
A20: Year | B20: LP Capital Called (outflow, negative) | C20: LP Distributions (inflow, positive) | D20: Net LP Cash Flow | E20: Notes
A21: Year 1 | B21: =-European_Waterfall!B24 -> -24500000 | C21: =0 -> 0 | D21: =B21+C21 -> -24500000 | E21: Deal 1: capital call Yr1
A22: Year 2 | B22: =-European_Waterfall!B25 -> -24500000 | C22: =0 -> 0 | D22: =B22+C22 -> -24500000 | E22: Deal 2: capital call Yr2
A23: Year 3 | B23: =-European_Waterfall!B26 -> -19600000 | C23: =0 -> 0 | D23: =B23+C23 -> -19600000
A24: Year 4 | B24: =-European_Waterfall!B27 -> -19600000 | C24: =Deal_Tracker!G5*European_Waterfall!C55/European_Waterfall!B19 -> 37471485 | D24: =B24+C24 -> 17871485 | E24: Deal 1 exits (LP share)
A25: Year 5 | B25: =-European_Waterfall!B28 -> -4900000 | C25: =Deal_Tracker!G6*European_Waterfall!C55/European_Waterfall!B19 -> 6245247.5 | D25: =B25+C25 -> 1345247.5 | E25: Deal 2 exits (LP share, loss deal)
A26: Year 6 | B26: =0 -> 0 | C26: =0 -> 0 | D26: =B26+C26 -> 0 | E26: No exits Year 6
A27: Year 7 | B27: =0 -> 0 | C27: =Deal_Tracker!G7*European_Waterfall!C55/European_Waterfall!B19 -> 62452475 | D27: =B27+C27 -> 62452475 | E27: Deal 3 exits
A28: Year 8 | B28: =0 -> 0 | C28: =Deal_Tracker!G8*European_Waterfall!C55/European_Waterfall!B19 -> 49069802 | D28: =B28+C28 -> 49069802 | E28: Deal 4 exits
A29: Year 9 | B29: =0 -> 0 | C29: =0 -> 0 | D29: =B29+C29 -> 0
A30: Year 10 | B30: =0 -> 0 | C30: =Deal_Tracker!G9*European_Waterfall!C55/European_Waterfall!B19 -> 24980990 | D30: =B30+C30 -> 24980990 | E30: Deal 5 exit/NAV (fund end)
A31: FUND IRR (LP Perspective) | B31: =IRR(D21:D30) -> 0.16578222 | C31: IRR on LP net cash flows (calls negative, distributions positive) — compound annual return
A33: SECTION C — EUROPEAN vs AMERICAN WATERFALL COMPARISON
A34: Metric | B34: European Waterfall | C34: American Waterfall | D34: Difference (Am − Eu)
A35: Total LP Distributions | B35: =European_Waterfall!C55 -> 180220000 | C35: =American_Waterfall!B23 -> 36600000 | D35: =C35-B35 -> -143620000
A36: Total GP Carry | B36: =European_Waterfall!D55 -> 21780000 | C36: =American_Waterfall!G24 -> 25000000 | D36: =C36-B36 -> 3220000
A37: GP Clawback Required | B37: =0 -> 0 | C37: =American_Waterfall!B32 -> 3220000 | D37: =C37-B37 -> 3220000
A38: GP Net Carry (after Clawback) | B38: =European_Waterfall!D55 -> 21780000 | C38: =American_Waterfall!B33 -> 21780000 | D38: =C38-B38 -> 0
A39: GP % of Total Profit | B39: =European_Waterfall!B66 -> 0.2 | C39: =American_Waterfall!B24/MAX(1,American_Waterfall!G24+American_Waterfall!B23-European_Waterfall!B11) -> 5400000 | D39: =C39-B39 -> 5399999.8
A41: KEY TALKING POINTS FOR INTERVIEWS
A42: 1. TVPI > 2.0x indicates strong fund performance; LP doubled their money on a total-value basis.
A43: 2. DPI is the 'proof of concept' metric — it measures cash actually returned to LPs, not paper gains.
A44: 3. RVPI decreases as deals are realised; a healthy fund sees DPI rise and RVPI fall over its life.
A45: 4. European waterfall protects LPs — GP cannot earn carry from one good deal while hiding losses in others.
A46: 5. American waterfall benefits GP cash flow but requires a clawback clause to prevent LP overpayment risk.
...
